Workbook

Sheet Resumen
A1: Inditex · Valoración por descuento de flujos (DCF)
A2: Proyecto de finanzas de Martín Peinado Miraflores · Modelo con hipótesis propias, uso formativo; no es una recomendación de inversión.
A4: Resultado del escenario activo (se actualiza solo)
A5: Escenario activo | B5: =Hipótesis!C41 -> Base
A6: WACC | B6: =Hipótesis!B22 -> 0.0897
A7: Crecimiento a perpetuidad (g) | B7: =Hipótesis!B23 -> 0.025
A8: Valor de la empresa (M€) | B8: =DCF!C32 -> 121062.8
A9: Valor del capital (M€) | B9: =DCF!C36 -> 131460.8
A10: Valor por acción hoy (€) | B10: =DCF!C40 -> 42.870653
A11: Precio de mercado (€) | B11: =Hipótesis!B9 -> 54.38
A12: Potencial frente al precio | B12: =DCF!C42 -> -0.21164669
A13: Valor terminal / valor de la empresa | B13: =DCF!C45 -> 0.58024892
A15: Los tres escenarios (foto estática, calculada con Python y verificada contra este Excel)
A16: Escenario | B16: WACC | C16: Valor por acción (€) | D16: Potencial vs precio | E16: Valor empresa (M€) | F16: VT / EV
A17: Bajo | B17: 0.0897 | C17: 32.726328 | D17: -0.39819184 | E17: 89955.715 | F17: 0.55656303
A18: Base | B18: 0.0897 | C18: 42.870653 | D18: -0.21164669 | E18: 121062.8 | F18: 0.58024892
A19: Alto | B19: 0.0897 | C19: 51.747125 | D19: -0.048416239 | E19: 148282.08 | F19: 0.59284911
A20: Precio de mercado | C20: =Hipótesis!B9 -> 54.38
A21: Para reproducir cada fila: cambia el selector de la hoja Hipótesis (celda B41). La foto no se actualiza sola.
A23: Cómo leer este libro
A24: Hipótesis: todas las entradas del modelo, con su fuente. Es la única hoja que hay que tocar.
A25: Histórico: cuentas de Inditex 2020-2025 y ratios calculados con fórmulas.
A26: DCF: proyección a 10 años del flujo de caja libre, valor terminal y valor por acción.
A27: Sensibilidad: cómo cambia el valor con el WACC y el crecimiento a perpetuidad.
A28: Comparables: qué valdría Inditex valorada como H&M, Fast Retailing o Next, y gráfico con todos los métodos.
A29: Colores: azul = dato o hipótesis editable · negro = fórmula · verde = enlace a otra hoja · amarillo = decisión clave.
A30: Cómo está planteado (y qué no hace)
A31: Los pagos por arrendamiento (alquiler de tiendas) se restan del flujo de caja como un coste operativo; por eso no se restan después como deuda.
A32: Se valora a 31/07/2026 (último balance, 1S2026) y se actualiza hasta el 07/10/2026. El precio incluye el dividendo de 0,875 € que se paga el 02/11/2026.
A33: El 2026E se valora solo en su segunda mitad, tomando la mitad del flujo anual (ignora la estacionalidad).
... A38: Monte Carlo (foto estática: 20.000 simulaciones con src/montecarlo.py)
A39: Mediana del valor por acción (€) | B39: 42.985505
A40: Media (€) | B40: 43.762494
A41: Percentil 5 (€): solo un 5 % de los casos vale menos | B41: 32.870177
A42: Percentil 95 (€): solo un 5 % de los casos vale más | B42: 57.320644
A43: Probabilidad de que el valor supere el precio de mercado | B43: 0.08925
A44: Probabilidad de que el valor supere 50 € | B44: 0.191
A45: Las hipótesis varían dentro de rangos razonables (beta ±0,10, prima de riesgo ±0,5 pp, crecimiento y margen ±1,2 pp, etc.). Ver docs/Guia_del_modelo.md. No se actualiza sola.
A47: Calidad contable (foto estática, src/calidad_contable.py): herramientas de cribado, no una prueba
A48: Ejercicio | B48: Altman Z'' (>2,6 segura) | C48: Beneish M (alerta > −1,78) | D48: Beneish M ajustado NIIF 16
...

Sheet Hipótesis
A1: Hipótesis del modelo
A2: Azul = dato/hipótesis que puedes editar · Amarillo = decisión clave · Negro = fórmula · Verde = enlace a otra hoja. M€ salvo indicación.
A4: 1. Fechas y mercado
A5: Fecha de valoración (precio de mercado) | B5: 46302 | D5: Fecha de la cotización usada
A6: Fecha del balance de partida | B6: 46234 | D6: Último balance publicado: 1S2026 (31/07/2026)
A7: Meses del ejercicio 2026 que quedan tras el balance | B7: 6 | D7: El ejercicio 2026 acaba el 31/01/2027
A8: Fracción del año 2026E que se valora | B8: =B7/12 -> 0.5 | D8: Simplificación: se valora la mitad del flujo anual de 2026E (ignora la estacionalidad)
A9: Precio de la acción (€) | B9: 54.38 | D9: es.investing.com, 07/10/2026. Cotiza con derecho a dividendo hasta el 29/10/2026
A10: Número de acciones (millones) | B10: 3115.9215 | D10: Resultados 1S2026 de Inditex
A11: Capitalización bursátil (M€) | B11: =B9*B10 -> 169443.81
A12: Días entre el balance y la fecha de valoración | B12: =B5-B6 -> 68
A14: 2. Tasa de descuento y crecimiento a perpetuidad
A15: Tipo libre de riesgo (rf) | B15: 0.0357 | D15: DECISIÓN DE MARTÍN (07/10/2026): bono alemán a 10 años, cierre 30/09/2026 (datosmacro). El bono español está en 4,11 %
A16: Beta | B16: 1 | D16: DECISIÓN DE MARTÍN. Regresión propia semanal a 5 años: 0,95-1,08 según índice (src/beta.py). Investing.com 0,90; sector (Damodaran) 0,79
A17: Prima de riesgo de mercado (ERP) | B17: 0.054 | D17: DECISIÓN DE MARTÍN. Mercado maduro 4,17 % (Damodaran, jul-2026) + riesgo-país ponderado por ventas de Inditex (estimación propia). España: 5,78 %
A18: Coste de los recursos propios (Ke = rf + beta × ERP) | B18: =B15+B16*B17 -> 0.0897 | D18: CAPM
A19: Coste de la deuda antes de impuestos | B19: 0.045 | D19: Irrelevante con peso de deuda 0 %
A20: Peso de la deuda D/(D+E) | B20: 0 | D20: Inditex no tiene deuda financiera relevante (caja neta)
A21: Tipo impositivo | B21: 0.225 | D21: Efectivo 2021-25 ≈ 22 %; 1S2026: 22,5 %
A22: WACC | B22: =B18*(1-B20)+B19*(1-B21)*B20 -> 0.0897 | D22: Los arrendamientos se tratan como coste operativo, no como deuda
A23: Crecimiento a perpetuidad (g) | B23: 0.025 | D23: DECISIÓN DE MARTÍN. Entre la inflación objetivo del BCE (2 %) y el crecimiento nominal esperado; menor que rf
A25: 3. Balance de partida (31/07/2026)
A26: Efectivo y equivalentes | B26: 4361 | D26: Resultados 1S2026
A27: Inversiones financieras temporales | B27: 6038 | D27: Resultados 1S2026
A28: Deuda financiera | B28: 1 | D28: Resultados 1S2026 (solo corriente)
A29: Posición financiera neta | B29: =B26+B27-B28 -> 10398 | D29: Coincide con los 10.398 M€ que publica Inditex
A30: Otros activos no operativos | B30: 0 | D30: 0 por prudencia: no se suman las inversiones por puesta en equivalencia (≈500 M€)
A31: Intereses minoritarios | B31: 0 | D31: Inditex no tiene minoritarios relevantes
A32: Pasivos por arrendamiento (informativo, no se resta) | B32: 6197 | D32: 4.549 + 1.648. No se restan porque el alquiler ya está dentro del flujo de caja (FCFF)
A34: 4. Parámetros operativos (iguales en todos los escenarios) | C34: 2025A
A35: Amortizaciones / ventas | B35: 0.082 | C35: =Histórico!H41 -> 0.082028898 | D35: Se mantiene el nivel de 2025
A36: Pagos por arrendamiento / ventas | B36: 0.046 | C36: =Histórico!H42 -> 0.046006422 | D36: Se mantiene el nivel de 2025
A37: Interés de arrendamientos / ventas | B37: 0.005 | C37: =Histórico!H43 -> 0.0053933373 | D37: Solo se usa para calcular el impuesto
A38: Circulante operativo / ventas | B38: -0.085 | C38: =Histórico!H44 -> -0.096678708 | D38: Media 2020-25 ≈ −8,6 %; al ser negativo, crecer libera caja
A40: 5. Escenarios (cambia el selector)
A41: Escenario activo (1 = Bajo, 2 = Base, 3 = Alto) | B41: 2 | C41: =CHOOSE(B41,"Bajo","Base","Alto") -> Base | D41: Las tres filas de cada bloque son hipótesis tuyas; la fila «Activo» es la que usa el modelo
A43: Crecimiento de ventas | D43: 2026E | E43: 2027E | F43: 2028E | G43: 2029E | H43: 2030E | I43: 2031E | J43: 2032E | K43: 2033E | L43: 2034E | M43: 2035E | N43: Bajo: la mitad del ritmo actual · Base: 7,5 % en 2026E (1S2026: +7,6 % reportado) con convergencia lineal al 3 % · Alto: mantiene ≈9 % (ritmo a tipo constante)
A44: Bajo | D44: 0.05 | E44: 0.045 | F44: 0.04 | G44: 0.035 | H44: 0.03 | I44: 0.03 | J44: 0.028 | K44: 0.026 | L44: 0.025 | M44: 0.025
A45: Base | D45: 0.075 | E45: 0.07 | F45: 0.065 | G45: 0.06 | H45: 0.055 | I45: 0.05 | J45: 0.045 | K45: 0.04 | L45: 0.035 | M45: 0.03
A46: Alto | D46: 0.09 | E46: 0.085 | F46: 0.08 | G46: 0.07 | H46: 0.065 | I46: 0.06 | J46: 0.05 | K46: 0.045 | L46: 0.04 | M46: 0.035
...

Sheet Histórico
A1: Histórico de Inditex (2020-2025)
A2: Fuente: cuentas anuales consolidadas de Inditex (inditex.com), extraídas con src/extract_statements.py. M€. El ejercicio N termina el 31/01/N+1.
C4: 2020 | D4: 2021 | E4: 2022 | F4: 2023 | G4: 2024 | H4: 2025
A5: Ventas | C5: 20402 | D5: 27716 | E5: 32569 | F5: 35947 | G5: 38632 | H5: 39864
A6: Coste de la mercancía | C6: -9013 | D6: -11902 | E6: -14011 | F6: -15186 | G6: -16288 | H6: -16642
A7: Margen bruto | C7: 11390 | D7: 15814 | E7: 18559 | F7: 20762 | G7: 22343 | H7: 23222
A8: EBITDA | C8: 4552 | D8: 7183 | E8: 8649 | F8: 9850 | G8: 10728 | H8: 11267
A9: Amortizaciones y depreciaciones | C9: -3045 | D9: -2901 | E9: -2899 | F9: -3041 | G9: -3174 | H9: -3270
A10: EBIT | C10: 1507 | D10: 4282 | E10: 5520 | F10: 6809 | G10: 7554 | H10: 7997
A11: Resultado antes de impuestos (BAI) | C11: 1401 | D11: 4199 | E11: 5358 | F11: 6870 | G11: 7577 | H11: 8020
A12: Impuesto sobre beneficios | C12: -297 | D12: -949 | E12: -1211 | F12: -1475 | G12: -1700 | H12: -1800
A13: Resultado neto | C13: 1104 | D13: 3250 | E13: 4147 | F13: 5395 | G13: 5877 | H13: 6220
A14: Balance (cierre de ejercicio)
A15: Existencias | C15: 2321 | D15: 3042 | E15: 3191 | F15: 2966 | G15: 3321 | H15: 3249
A16: Deudores | C16: 715 | D16: 842 | E16: 851 | F16: 1038 | G16: 1088 | H16: 1166
A17: Acreedores | C17: 4659 | D17: 6199 | E17: 6297 | F17: 7072 | G17: 8278 | H17: 8269
A18: Circulante operativo (existencias + deudores − acreedores) | C18: =C15+C16-C17 -> -1623 | D18: =D15+D16-D17 -> -2315 | E18: =E15+E16-E17 -> -2255 | F18: =F15+F16-F17 -> -3068 | G18: =G15+G16-G17 -> -3869 | H18: =H15+H16-H17 -> -3854
A19: Efectivo y equivalentes | C19: 7398 | D19: 7021 | E19: 5561 | F19: 7007 | G19: 6382 | H19: 5276
A20: Inversiones financieras temporales | C20: 176 | D20: 2374 | E20: 4522 | F20: 4415 | G20: 5120 | H20: 5684
A21: Deuda financiera (corriente + no corriente) | C21: 14 | D21: 36 | E21: 13 | F21: 16 | G21: 7 | H21: 2
A22: Pasivo por arrendamiento a largo plazo | C22: 4599 | D22: 4262 | E22: 3924 | F22: 4123 | G22: 4180 | H22: 4394
A23: Pasivo por arrendamiento a corto plazo | C23: 1552 | D23: 1562 | E23: 1517 | F23: 1428 | G23: 1542 | H23: 1539
A24: Patrimonio neto | C24: 14550 | D24: 15759 | E24: 17033 | F24: 18672 | G24: 19676 | H24: 20395
A25: Total activo | C25: 26418 | D25: 28945 | E25: 29983 | F25: 32735 | G25: 34714 | H25: 35638
A26: Flujos de caja
A27: Flujo de explotación (CFO) | C27: 3017 | D27: 6754 | E27: 6674 | F27: 8667 | G27: 9288 | H27: 9232
A28: Capex en inmovilizado material | C28: -467 | D28: -666 | E28: -1027 | F28: -1399 | G28: -2207 | H28: -2193
A29: Capex en inmovilizado intangible | C29: -241 | D29: -460 | E29: -388 | F29: -473 | G29: -465 | H29: -519
A30: Pagos por arrendamiento (renta fija) | C30: -1673 | D30: -1668 | E30: -1621 | F30: -1733 | G30: -1802 | H30: -1834
A31: Gasto financiero por arrendamiento | C31: 120 | D31: 92 | E31: 116 | F31: 196 | G31: 223 | H31: 215
A32: Dividendos pagados | C32: -1090 | D32: -2192 | E32: -2914 | F32: -3744 | G32: -4797 | H32: -5235
A34: Ratios (fórmulas)
A35: Crecimiento de ventas | D35: =D5/C5-1 -> 0.35849427 | E35: =E5/D5-1 -> 0.17509742 | F35: =F5/E5-1 -> 0.10371826 | G35: =G5/F5-1 -> 0.074693298 | H35: =H5/G5-1 -> 0.031890661
A36: Margen bruto | C36: =C7/C5 -> 0.5582786 | D36: =D7/D5 -> 0.57057295 | E36: =E7/E5 -> 0.56983635 | F36: =F7/F5 -> 0.57757254 | G36: =G7/G5 -> 0.57835473 | H36: =H7/H5 -> 0.5825306
A37: Margen EBITDA | C37: =C8/C5 -> 0.22311538 | D37: =D8/D5 -> 0.25916438 | E37: =E8/E5 -> 0.26555927 | F37: =F8/F5 -> 0.27401452 | G37: =G8/G5 -> 0.27769725 | H37: =H8/H5 -> 0.28263596
A38: Margen EBIT | C38: =C10/C5 -> 0.073865307 | D38: =D10/D5 -> 0.1544956 | E38: =E10/E5 -> 0.16948632 | F38: =F10/F5 -> 0.18941775 | G38: =G10/G5 -> 0.19553738 | H38: =H10/H5 -> 0.20060706
A39: Margen neto | C39: =C13/C5 -> 0.054112342 | D39: =D13/D5 -> 0.11726079 | E39: =E13/E5 -> 0.12732967 | F39: =F13/F5 -> 0.15008207 | G39: =G13/G5 -> 0.15212777 | H39: =H13/H5 -> 0.1560305
A40: Tipo impositivo efectivo | C40: =-C12/C11 -> 0.21199143 | D40: =-D12/D11 -> 0.22600619 | E40: =-E12/E11 -> 0.22601717 | F40: =-F12/F11 -> 0.2147016 | G40: =-G12/G11 -> 0.2243632 | H40: =-H12/H11 -> 0.2244389
A41: Amortizaciones / ventas | C41: =-C9/C5 -> 0.14925007 | D41: =-D9/D5 -> 0.10466878 | E41: =-E9/E5 -> 0.089011023 | F41: =-F9/F5 -> 0.084596767 | G41: =-G9/G5 -> 0.082159867 | H41: =-H9/H5 -> 0.082028898
A42: Pagos por arrendamiento / ventas | C42: =-C30/C5 -> 0.082001765 | D42: =-D30/D5 -> 0.060181844 | E42: =-E30/E5 -> 0.049771255 | F42: =-F30/F5 -> 0.048209865 | G42: =-G30/G5 -> 0.046645268 | H42: =-H30/H5 -> 0.046006422
...

Sheet DCF
A1: DCF · flujo de caja libre de la empresa (FCFF)
A2: ="Escenario: "&Hipótesis!C41&" · WACC "&ROUND(Hipótesis!B22*100,2)&" % · g "&ROUND(Hipótesis!B23*100,2)&" %" -> Escenario: Base · WACC 8,97 % · g 2,5 %
A4: M€ | C4: 2025A | D4: 2026E | E4: 2027E | F4: 2028E | G4: 2029E | H4: 2030E | I4: 2031E | J4: 2032E | K4: 2033E | L4: 2034E | M4: 2035E
A5: Ventas | C5: =Histórico!H5 -> 39864 | D5: =C5*(1+D6) -> 42853.8 | E5: =D5*(1+E6) -> 45853.566 | F5: =E5*(1+F6) -> 48834.048 | G5: =F5*(1+G6) -> 51764.091 | H5: =G5*(1+H6) -> 54611.116 | I5: =H5*(1+I6) -> 57341.671 | J5: =I5*(1+J6) -> 59922.047 | K5: =J5*(1+K6) -> 62318.929 | ... M5: =L5*(1+M6) -> 66435.094
A6: Crecimiento | C6: =Histórico!H35 -> 0.031890661 | D6: =Hipótesis!D47 -> 0.075 | E6: =Hipótesis!E47 -> 0.07 | F6: =Hipótesis!F47 -> 0.065 | G6: =Hipótesis!G47 -> 0.06 | H6: =Hipótesis!H47 -> 0.055 | I6: =Hipótesis!I47 -> 0.05 | J6: =Hipótesis!J47 -> 0.045 | K6: =Hipótesis!K47 -> 0.04 | ... M6: =Hipótesis!M47 -> 0.03
A7: Margen EBIT | C7: =Histórico!H38 -> 0.20060706 | D7: =Hipótesis!D53 -> 0.2 | E7: =Hipótesis!E53 -> 0.2 | F7: =Hipótesis!F53 -> 0.2 | G7: =Hipótesis!G53 -> 0.2 | H7: =Hipótesis!H53 -> 0.2 | I7: =Hipótesis!I53 -> 0.2 | J7: =Hipótesis!J53 -> 0.2 | K7: =Hipótesis!K53 -> 0.2 | ... M7: =Hipótesis!M53 -> 0.2
A8: EBIT | C8: =Histórico!H10 -> 7997 | D8: =D5*D7 -> 8570.76 | E8: =E5*E7 -> 9170.7132 | F8: =F5*F7 -> 9766.8096 | G8: =G5*G7 -> 10352.818 | H8: =H5*H7 -> 10922.223 | I8: =I5*I7 -> 11468.334 | J8: =J5*J7 -> 11984.409 | K8: =K5*K7 -> 12463.786 | ... M8: =M5*M7 -> 13287.019
A9: Amortizaciones | C9: =-Histórico!H9 -> 3270 | D9: =D5*Hipótesis!$B$35 -> 3514.0116 | E9: =E5*Hipótesis!$B$35 -> 3759.9924 | F9: =F5*Hipótesis!$B$35 -> 4004.3919 | G9: =G5*Hipótesis!$B$35 -> 4244.6554 | H9: =H5*Hipótesis!$B$35 -> 4478.1115 | I9: =I5*Hipótesis!$B$35 -> 4702.0171 | J9: =J5*Hipótesis!$B$35 -> 4913.6078 | K9: =K5*Hipótesis!$B$35 -> 5110.1521 | ... M9: =M5*Hipótesis!$B$35 -> 5447.6777
A10: EBITDA | C10: =Histórico!H8 -> 11267 | D10: =D8+D9 -> 12084.772 | E10: =E8+E9 -> 12930.706 | F10: =F8+F9 -> 13771.201 | G10: =G8+G9 -> 14597.474 | H10: =H8+H9 -> 15400.335 | I10: =I8+I9 -> 16170.351 | J10: =J8+J9 -> 16898.017 | K10: =K8+K9 -> 17573.938 | ... M10: =M8+M9 -> 18734.696
A11: (−) Pagos por arrendamiento | C11: =Histórico!H30 -> -1834 | D11: =-D5*Hipótesis!$B$36 -> -1971.2748 | E11: =-E5*Hipótesis!$B$36 -> -2109.264 | F11: =-F5*Hipótesis!$B$36 -> -2246.3662 | G11: =-G5*Hipótesis!$B$36 -> -2381.1482 | H11: =-H5*Hipótesis!$B$36 -> -2512.1113 | I11: =-I5*Hipótesis!$B$36 -> -2637.7169 | J11: =-J5*Hipótesis!$B$36 -> -2756.4141 | K11: =-K5*Hipótesis!$B$36 -> -2866.6707 | ... M11: =-M5*Hipótesis!$B$36 -> -3056.0143
A12: Memo: interés de arrendamientos | C12: =Histórico!H31 -> 215 | D12: =D5*Hipótesis!$B$37 -> 214.269 | E12: =E5*Hipótesis!$B$37 -> 229.26783 | F12: =F5*Hipótesis!$B$37 -> 244.17024 | G12: =G5*Hipótesis!$B$37 -> 258.82045 | H12: =H5*Hipótesis!$B$37 -> 273.05558 | I12: =I5*Hipótesis!$B$37 -> 286.70836 | J12: =J5*Hipótesis!$B$37 -> 299.61023 | K12: =K5*Hipótesis!$B$37 -> 311.59464 | ... M12: =M5*Hipótesis!$B$37 -> 332.17547
A13: (−) Impuestos sobre EBIT − interés de arrend. | D13: =-Hipótesis!$B$21*MAX(D8-D12,0) -> -1880.2105 | E13: =-Hipótesis!$B$21*MAX(E8-E12,0) -> -2011.8252 | F13: =-Hipótesis!$B$21*MAX(F8-F12,0) -> -2142.5938 | G13: =-Hipótesis!$B$21*MAX(G8-G12,0) -> -2271.1495 | H13: =-Hipótesis!$B$21*MAX(H8-H12,0) -> -2396.0627 | I13: =-Hipótesis!$B$21*MAX(I8-I12,0) -> -2515.8658 | J13: =-Hipótesis!$B$21*MAX(J8-J12,0) -> -2629.0798 | K13: =-Hipótesis!$B$21*MAX(K8-K12,0) -> -2734.243 | ... M13: =-Hipótesis!$B$21*MAX(M8-M12,0) -> -2914.8397
A14: (−) Capex | C14: =Histórico!H28+Histórico!H29 -> -2712 | D14: =-D5*Hipótesis!D59 -> -2485.5204 | E14: =-E5*Hipótesis!E59 -> -2567.7997 | F14: =-F5*Hipótesis!F59 -> -2637.0386 | G14: =-G5*Hipótesis!G59 -> -2691.7327 | H14: =-H5*Hipótesis!H59 -> -2730.5558 | I14: =-I5*Hipótesis!I59 -> -2867.0836 | J14: =-J5*Hipótesis!J59 -> -2996.1023 | K14: =-K5*Hipótesis!K59 -> -3115.9464 | ... M14: =-M5*Hipótesis!M59 -> -3321.7547
A15: Memo: saldo de circulante operativo | C15: =Histórico!H18 -> -3854 | D15: =D5*Hipótesis!$B$38 -> -3642.573 | E15: =E5*Hipótesis!$B$38 -> -3897.5531 | F15: =F5*Hipótesis!$B$38 -> -4150.8941 | G15: =G5*Hipótesis!$B$38 -> -4399.9477 | H15: =H5*Hipótesis!$B$38 -> -4641.9448 | I15: =I5*Hipótesis!$B$38 -> -4874.0421 | J15: =J5*Hipótesis!$B$38 -> -5093.374 | K15: =K5*Hipótesis!$B$38 -> -5297.1089 | ... M15: =M5*Hipótesis!$B$38 -> -5646.983
A16: (−) Aumento / (+) disminución del circulante | D16: =C15-D15 -> -211.427 | E16: =D15-E15 -> 254.98011 | F16: =E15-F15 -> 253.34095 | G16: =F15-G15 -> 249.05364 | H16: =G15-H15 -> 241.99712 | I16: =H15-I15 -> 232.09724 | J16: =I15-J15 -> 219.33189 | K16: =J15-K15 -> 203.73496 | ... M16: =L15-M15 -> 164.47523
A17: FCFF (flujo de caja libre de la empresa) | D17: =D10+D11+D13+D14+D16 -> 5536.3389 | E17: =E10+E11+E13+E14+E16 -> 6496.7968 | F17: =F10+F11+F13+F14+F16 -> 6998.5438 | G17: =G10+G11+G13+G14+G16 -> 7502.4968 | H17: =H10+H11+H13+H14+H16 -> 8003.6019 | I17: =I10+I11+I13+I14+I16 -> 8381.7823 | J17: =J10+J11+J13+J14+J16 -> 8735.7528 | K17: =K10+K11+K13+K14+K16 -> 9060.8127 | ... M17: =M10+M11+M13+M14+M16 -> 9606.5629
A18: Memo: FCF 2025A tras arrendamientos (reportado, no comparable 1:1) | C18: =Histórico!H46 -> 4686
A20: Fracción del año que se valora | D20: =Hipótesis!B8 -> 0.5 | E20: 1 | F20: 1 | G20: 1 | H20: 1 | I20: 1 | J20: 1 | K20: 1 | L20: 1 | M20: 1
A21: FCFF a valorar | D21: =D17*D20 -> 2768.1695 | E21: =E17*E20 -> 6496.7968 | F21: =F17*F20 -> 6998.5438 | G21: =G17*G20 -> 7502.4968 | H21: =H17*H20 -> 8003.6019 | I21: =I17*I20 -> 8381.7823 | J21: =J17*J20 -> 8735.7528 | K21: =K17*K20 -> 9060.8127 | ... M21: =M17*M20 -> 9606.5629
A22: Tiempo de descuento (años desde 31/07/2026, mitad de periodo) | D22: =Hipótesis!B8/2 -> 0.25 | E22: =Hipótesis!B8+0.5 -> 1 | F22: =E22+1 -> 2 | G22: =F22+1 -> 3 | H22: =G22+1 -> 4 | I22: =H22+1 -> 5 | J22: =I22+1 -> 6 | K22: =J22+1 -> 7 | L22: =K22+1 -> 8 | M22: =L22+1 -> 9
A23: Factor de descuento | D23: =1/(1+Hipótesis!$B$22)^D22 -> 0.97875335 | E23: =1/(1+Hipótesis!$B$22)^E22 -> 0.91768377 | F23: =1/(1+Hipótesis!$B$22)^F22 -> 0.84214349 | G23: =1/(1+Hipótesis!$B$22)^G22 -> 0.77282141 | H23: =1/(1+Hipótesis!$B$22)^H22 -> 0.70920567 | I23: =1/(1+Hipótesis!$B$22)^I22 -> 0.65082653 | J23: =1/(1+Hipótesis!$B$22)^J22 -> 0.59725294 | K23: =1/(1+Hipótesis!$B$22)^K22 -> 0.54808933 | ... M23: =1/(1+Hipótesis!$B$22)^M22 -> 0.46156986
A24: Valor actual del FCFF | D24: =D21*D23 -> 2709.3551 | E24: =E21*E23 -> 5962.0049 | F24: =F21*F23 -> 5893.7781 | G24: =G21*G23 -> 5798.0902 | H24: =H21*H23 -> 5676.1998 | I24: =I21*I23 -> 5455.0863 | J24: =J21*J23 -> 5217.454 | K24: =K21*K23 -> 4966.1347 | ... M24: =M21*M23 -> 4434.0999
A26: Valoración
A27: Suma del valor actual de los FCFF (2026E-2035E) | C27: =SUM(D24:M24) -> 50816.242
A28: FCFF del último año explícito (2035E) | C28: =M17 -> 9606.5629
A29: Valor terminal (Gordon: FCFF × (1+g) / (WACC − g)) | C29: =C28*(1+Hipótesis!B23)/(Hipótesis!B22-Hipótesis!B23) -> 152190.53
A30: Factor de descuento del valor terminal | C30: =M23 -> 0.46156986
A31: Valor actual del valor terminal | C31: =C29*C30 -> 70246.56
A32: Valor de la empresa (EV) | C32: =C27+C31 -> 121062.8
A33: (+) Posición financiera neta | C33: =Hipótesis!B29 -> 10398
A34: (+) Otros activos no operativos | C34: =Hipótesis!B30 -> 0
A35: (−) Intereses minoritarios | C35: =-Hipótesis!B31 -> 0
A36: Valor del capital (equity) a 31/07/2026 | C36: =SUM(C32:C35) -> 131460.8
A37: Acciones (millones) | C37: =Hipótesis!B10 -> 3115.9215
A38: Valor por acción a 31/07/2026 | C38: =C36/C37 -> 42.190023
A39: Factor para actualizar hasta la fecha de valoración | C39: =(1+Hipótesis!B22)^(Hipótesis!B12/365) -> 1.0161325
A40: VALOR POR ACCIÓN HOY | C40: =C38*C39 -> 42.870653
A41: Precio de mercado | C41: =Hipótesis!B9 -> 54.38
A42: Potencial frente al precio de mercado | C42: =C40/C41-1 -> -0.21164669
A44: Controles de sensatez
...

Sheet Sensibilidad
A1: Sensibilidad del valor por acción
A2: Cada celda recalcula la valoración con otro WACC y otro g, manteniendo el escenario activo. Verde = por encima del precio de mercado; rojo = por debajo.
A4: Paso del WACC | B4: 0.005
A5: Paso de g | B5: 0.005
A7: Valor por acción hoy (€)
A8: WACC ↓ · g → | B8: =Hipótesis!$B$23+(0-2)*$B$5 -> 0.015 | C8: =Hipótesis!$B$23+(1-2)*$B$5 -> 0.02 | D8: =Hipótesis!$B$23+(2-2)*$B$5 -> 0.025 | E8: =Hipótesis!$B$23+(3-2)*$B$5 -> 0.03 | F8: =Hipótesis!$B$23+(4-2)*$B$5 -> 0.035
A9: =Hipótesis!$B$22+(0-3)*$B$4 -> 0.0747 | B9: =((SUMPRODUCT(DCF!$D$21:$M$21,(1+$A9)^(-DCF!$D$22:$M$22))+DCF!$M$17*(1+B$8)/($A9-B$8)*(1+$A9)^(-DCF!$M$22)+Hipótesis!$B$29+Hipótesis!$B$30-Hipótesis!$B$31)/Hipótesis!$B$10*(1+$A9)^(Hipótesis!$B$12/365)) -> 48.769585 | C9: =((SUMPRODUCT(DCF!$D$21:$M$21,(1+$A9)^(-DCF!$D$22:$M$22))+DCF!$M$17*(1+C$8)/($A9-C$8)*(1+$A9)^(-DCF!$M$22)+Hipótesis!$B$29+Hipótesis!$B$30-Hipótesis!$B$31)/Hipótesis!$B$10*(1+$A9)^(Hipótesis!$B$12/365)) -> 51.458152 | D9: =((SUMPRODUCT(DCF!$D$21:$M$21,(1+$A9)^(-DCF!$D$22:$M$22))+DCF!$M$17*(1+D$8)/($A9-D$8)*(1+$A9)^(-DCF!$M$22)+Hipótesis!$B$29+Hipótesis!$B$30-Hipótesis!$B$31)/Hipótesis!$B$10*(1+$A9)^(Hipótesis!$B$12/365)) -> 54.687677 | E9: =((SUMPRODUCT(DCF!$D$21:$M$21,(1+$A9)^(-DCF!$D$22:$M$22))+DCF!$M$17*(1+E$8)/($A9-E$8)*(1+$A9)^(-DCF!$M$22)+Hipótesis!$B$29+Hipótesis!$B$30-Hipótesis!$B$31)/Hipótesis!$B$10*(1+$A9)^(Hipótesis!$B$12/365)) -> 58.639691 | F9: =((SUMPRODUCT(DCF!$D$21:$M$21,(1+$A9)^(-DCF!$D$22:$M$22))+DCF!$M$17*(1+F$8)/($A9-F$8)*(1+$A9)^(-DCF!$M$22)+Hipótesis!$B$29+Hipótesis!$B$30-Hipótesis!$B$31)/Hipótesis!$B$10*(1+$A9)^(Hipótesis!$B$12/365)) -> 63.587174
A10: =Hipótesis!$B$22+(1-3)*$B$4 -> 0.0797 | B10: =((SUMPRODUCT(DCF!$D$21:$M$21,(1+$A10)^(-DCF!$D$22:$M$22))+DCF!$M$17*(1+B$8)/($A10-B$8)*(1+$A10)^(-DCF!$M$22)+Hipótesis!$B$29+Hipótesis!$B$30-Hipótesis!$B$31)/Hipótesis!$B$10*(1+$A10)^(Hipótesis!$B$12/365)) -> 45.241425 | C10: =((SUMPRODUCT(DCF!$D$21:$M$21,(1+$A10)^(-DCF!$D$22:$M$22))+DCF!$M$17*(1+C$8)/($A10-C$8)*(1+$A10)^(-DCF!$M$22)+Hipótesis!$B$29+Hipótesis!$B$30-Hipótesis!$B$31)/Hipótesis!$B$10*(1+$A10)^(Hipótesis!$B$12/365)) -> 47.433485 | D10: =((SUMPRODUCT(DCF!$D$21:$M$21,(1+$A10)^(-DCF!$D$22:$M$22))+DCF!$M$17*(1+D$8)/($A10-D$8)*(1+$A10)^(-DCF!$M$22)+Hipótesis!$B$29+Hipótesis!$B$30-Hipótesis!$B$31)/Hipótesis!$B$10*(1+$A10)^(Hipótesis!$B$12/365)) -> 50.026288 | E10: =((SUMPRODUCT(DCF!$D$21:$M$21,(1+$A10)^(-DCF!$D$22:$M$22))+DCF!$M$17*(1+E$8)/($A10-E$8)*(1+$A10)^(-DCF!$M$22)+Hipótesis!$B$29+Hipótesis!$B$30-Hipótesis!$B$31)/Hipótesis!$B$10*(1+$A10)^(Hipótesis!$B$12/365)) -> 53.140781 | F10: =((SUMPRODUCT(DCF!$D$21:$M$21,(1+$A10)^(-DCF!$D$22:$M$22))+DCF!$M$17*(1+F$8)/($A10-F$8)*(1+$A10)^(-DCF!$M$22)+Hipótesis!$B$29+Hipótesis!$B$30-Hipótesis!$B$31)/Hipótesis!$B$10*(1+$A10)^(Hipótesis!$B$12/365)) -> 56.952029
A11: =Hipótesis!$B$22+(2-3)*$B$4 -> 0.0847 | B11: =((SUMPRODUCT(DCF!$D$21:$M$21,(1+$A11)^(-DCF!$D$22:$M$22))+DCF!$M$17*(1+B$8)/($A11-B$8)*(1+$A11)^(-DCF!$M$22)+Hipótesis!$B$29+Hipótesis!$B$30-Hipótesis!$B$31)/Hipótesis!$B$10*(1+$A11)^(Hipótesis!$B$12/365)) -> 42.222475 | C11: =((SUMPRODUCT(DCF!$D$21:$M$21,(1+$A11)^(-DCF!$D$22:$M$22))+DCF!$M$17*(1+C$8)/($A11-C$8)*(1+$A11)^(-DCF!$M$22)+Hipótesis!$B$29+Hipótesis!$B$30-Hipótesis!$B$31)/Hipótesis!$B$10*(1+$A11)^(Hipótesis!$B$12/365)) -> 44.033463 | D11: =((SUMPRODUCT(DCF!$D$21:$M$21,(1+$A11)^(-DCF!$D$22:$M$22))+DCF!$M$17*(1+D$8)/($A11-D$8)*(1+$A11)^(-DCF!$M$22)+Hipótesis!$B$29+Hipótesis!$B$30-Hipótesis!$B$31)/Hipótesis!$B$10*(1+$A11)^(Hipótesis!$B$12/365)) -> 46.147799 | E11: =((SUMPRODUCT(DCF!$D$21:$M$21,(1+$A11)^(-DCF!$D$22:$M$22))+DCF!$M$17*(1+E$8)/($A11-E$8)*(1+$A11)^(-DCF!$M$22)+Hipótesis!$B$29+Hipótesis!$B$30-Hipótesis!$B$31)/Hipótesis!$B$10*(1+$A11)^(Hipótesis!$B$12/365)) -> 48.648668 | F11: =((SUMPRODUCT(DCF!$D$21:$M$21,(1+$A11)^(-DCF!$D$22:$M$22))+DCF!$M$17*(1+F$8)/($A11-F$8)*(1+$A11)^(-DCF!$M$22)+Hipótesis!$B$29+Hipótesis!$B$30-Hipótesis!$B$31)/Hipótesis!$B$10*(1+$A11)^(Hipótesis!$B$12/365)) -> 51.65273
A12: =Hipótesis!$B$22+(3-3)*$B$4 -> 0.0897 | B12: =((SUMPRODUCT(DCF!$D$21:$M$21,(1+$A12)^(-DCF!$D$22:$M$22))+DCF!$M$17*(1+B$8)/($A12-B$8)*(1+$A12)^(-DCF!$M$22)+Hipótesis!$B$29+Hipótesis!$B$30-Hipótesis!$B$31)/Hipótesis!$B$10*(1+$A12)^(Hipótesis!$B$12/365)) -> 39.6104 | C12: =((SUMPRODUCT(DCF!$D$21:$M$21,(1+$A12)^(-DCF!$D$22:$M$22))+DCF!$M$17*(1+C$8)/($A12-C$8)*(1+$A12)^(-DCF!$M$22)+Hipótesis!$B$29+Hipótesis!$B$30-Hipótesis!$B$31)/Hipótesis!$B$10*(1+$A12)^(Hipótesis!$B$12/365)) -> 41.123588 | D12: =((SUMPRODUCT(DCF!$D$21:$M$21,(1+$A12)^(-DCF!$D$22:$M$22))+DCF!$M$17*(1+D$8)/($A12-D$8)*(1+$A12)^(-DCF!$M$22)+Hipótesis!$B$29+Hipótesis!$B$30-Hipótesis!$B$31)/Hipótesis!$B$10*(1+$A12)^(Hipótesis!$B$12/365)) -> 42.870653 | E12: =((SUMPRODUCT(DCF!$D$21:$M$21,(1+$A12)^(-DCF!$D$22:$M$22))+DCF!$M$17*(1+E$8)/($A12-E$8)*(1+$A12)^(-DCF!$M$22)+Hipótesis!$B$29+Hipótesis!$B$30-Hipótesis!$B$31)/Hipótesis!$B$10*(1+$A12)^(Hipótesis!$B$12/365)) -> 44.910359 | F12: =((SUMPRODUCT(DCF!$D$21:$M$21,(1+$A12)^(-DCF!$D$22:$M$22))+DCF!$M$17*(1+F$8)/($A12-F$8)*(1+$A12)^(-DCF!$M$22)+Hipótesis!$B$29+Hipótesis!$B$30-Hipótesis!$B$31)/Hipótesis!$B$10*(1+$A12)^(Hipótesis!$B$12/365)) -> 47.322955
A13: =Hipótesis!$B$22+(4-3)*$B$4 -> 0.0947 | B13: =((SUMPRODUCT(DCF!$D$21:$M$21,(1+$A13)^(-DCF!$D$22:$M$22))+DCF!$M$17*(1+B$8)/($A13-B$8)*(1+$A13)^(-DCF!$M$22)+Hipótesis!$B$29+Hipótesis!$B$30-Hipótesis!$B$31)/Hipótesis!$B$10*(1+$A13)^(Hipótesis!$B$12/365)) -> 37.328547 | C13: =((SUMPRODUCT(DCF!$D$21:$M$21,(1+$A13)^(-DCF!$D$22:$M$22))+DCF!$M$17*(1+C$8)/($A13-C$8)*(1+$A13)^(-DCF!$M$22)+Hipótesis!$B$29+Hipótesis!$B$30-Hipótesis!$B$31)/Hipótesis!$B$10*(1+$A13)^(Hipótesis!$B$12/365)) -> 38.605375 | D13: =((SUMPRODUCT(DCF!$D$21:$M$21,(1+$A13)^(-DCF!$D$22:$M$22))+DCF!$M$17*(1+D$8)/($A13-D$8)*(1+$A13)^(-DCF!$M$22)+Hipótesis!$B$29+Hipótesis!$B$30-Hipótesis!$B$31)/Hipótesis!$B$10*(1+$A13)^(Hipótesis!$B$12/365)) -> 40.065392 | E13: =((SUMPRODUCT(DCF!$D$21:$M$21,(1+$A13)^(-DCF!$D$22:$M$22))+DCF!$M$17*(1+E$8)/($A13-E$8)*(1+$A13)^(-DCF!$M$22)+Hipótesis!$B$29+Hipótesis!$B$30-Hipótesis!$B$31)/Hipótesis!$B$10*(1+$A13)^(Hipótesis!$B$12/365)) -> 41.751069 | F13: =((SUMPRODUCT(DCF!$D$21:$M$21,(1+$A13)^(-DCF!$D$22:$M$22))+DCF!$M$17*(1+F$8)/($A13-F$8)*(1+$A13)^(-DCF!$M$22)+Hipótesis!$B$29+Hipótesis!$B$30-Hipótesis!$B$31)/Hipótesis!$B$10*(1+$A13)^(Hipótesis!$B$12/365)) -> 43.719103
A14: =Hipótesis!$B$22+(5-3)*$B$4 -> 0.0997 | B14: =((SUMPRODUCT(DCF!$D$21:$M$21,(1+$A14)^(-DCF!$D$22:$M$22))+DCF!$M$17*(1+B$8)/($A14-B$8)*(1+$A14)^(-DCF!$M$22)+Hipótesis!$B$29+Hipótesis!$B$30-Hipótesis!$B$31)/Hipótesis!$B$10*(1+$A14)^(Hipótesis!$B$12/365)) -> 35.318368 | C14: =((SUMPRODUCT(DCF!$D$21:$M$21,(1+$A14)^(-DCF!$D$22:$M$22))+DCF!$M$17*(1+C$8)/($A14-C$8)*(1+$A14)^(-DCF!$M$22)+Hipótesis!$B$29+Hipótesis!$B$30-Hipótesis!$B$31)/Hipótesis!$B$10*(1+$A14)^(Hipótesis!$B$12/365)) -> 36.405057 | D14: =((SUMPRODUCT(DCF!$D$21:$M$21,(1+$A14)^(-DCF!$D$22:$M$22))+DCF!$M$17*(1+D$8)/($A14-D$8)*(1+$A14)^(-DCF!$M$22)+Hipótesis!$B$29+Hipótesis!$B$30-Hipótesis!$B$31)/Hipótesis!$B$10*(1+$A14)^(Hipótesis!$B$12/365)) -> 37.637221 | E14: =((SUMPRODUCT(DCF!$D$21:$M$21,(1+$A14)^(-DCF!$D$22:$M$22))+DCF!$M$17*(1+E$8)/($A14-E$8)*(1+$A14)^(-DCF!$M$22)+Hipótesis!$B$29+Hipótesis!$B$30-Hipótesis!$B$31)/Hipótesis!$B$10*(1+$A14)^(Hipótesis!$B$12/365)) -> 39.046165 | F14: =((SUMPRODUCT(DCF!$D$21:$M$21,(1+$A14)^(-DCF!$D$22:$M$22))+DCF!$M$17*(1+F$8)/($A14-F$8)*(1+$A14)^(-DCF!$M$22)+Hipótesis!$B$29+Hipótesis!$B$30-Hipótesis!$B$31)/Hipótesis!$B$10*(1+$A14)^(Hipótesis!$B$12/365)) -> 40.672875
A15: =Hipótesis!$B$22+(6-3)*$B$4 -> 0.1047 | B15: =((SUMPRODUCT(DCF!$D$21:$M$21,(1+$A15)^(-DCF!$D$22:$M$22))+DCF!$M$17*(1+B$8)/($A15-B$8)*(1+$A15)^(-DCF!$M$22)+Hipótesis!$B$29+Hipótesis!$B$30-Hipótesis!$B$31)/Hipótesis!$B$10*(1+$A15)^(Hipótesis!$B$12/365)) -> 33.534369 | C15: =((SUMPRODUCT(DCF!$D$21:$M$21,(1+$A15)^(-DCF!$D$22:$M$22))+DCF!$M$17*(1+C$8)/($A15-C$8)*(1+$A15)^(-DCF!$M$22)+Hipótesis!$B$29+Hipótesis!$B$30-Hipótesis!$B$31)/Hipótesis!$B$10*(1+$A15)^(Hipótesis!$B$12/365)) -> 34.466286 | D15: =((SUMPRODUCT(DCF!$D$21:$M$21,(1+$A15)^(-DCF!$D$22:$M$22))+DCF!$M$17*(1+D$8)/($A15-D$8)*(1+$A15)^(-DCF!$M$22)+Hipótesis!$B$29+Hipótesis!$B$30-Hipótesis!$B$31)/Hipótesis!$B$10*(1+$A15)^(Hipótesis!$B$12/365)) -> 35.515131 | E15: =((SUMPRODUCT(DCF!$D$21:$M$21,(1+$A15)^(-DCF!$D$22:$M$22))+DCF!$M$17*(1+E$8)/($A15-E$8)*(1+$A15)^(-DCF!$M$22)+Hipótesis!$B$29+Hipótesis!$B$30-Hipótesis!$B$31)/Hipótesis!$B$10*(1+$A15)^(Hipótesis!$B$12/365)) -> 36.704384 | F15: =((SUMPRODUCT(DCF!$D$21:$M$21,(1+$A15)^(-DCF!$D$22:$M$22))+DCF!$M$17*(1+F$8)/($A15-F$8)*(1+$A15)^(-DCF!$M$22)+Hipótesis!$B$29+Hipótesis!$B$30-Hipótesis!$B$31)/Hipótesis!$B$10*(1+$A15)^(Hipótesis!$B$12/365)) -> 38.064262
A18: Potencial frente al precio de mercado
A19: WACC ↓ · g → | B19: =Hipótesis!$B$23+(0-2)*$B$5 -> 0.015 | C19: =Hipótesis!$B$23+(1-2)*$B$5 -> 0.02 | D19: =Hipótesis!$B$23+(2-2)*$B$5 -> 0.025 | E19: =Hipótesis!$B$23+(3-2)*$B$5 -> 0.03 | F19: =Hipótesis!$B$23+(4-2)*$B$5 -> 0.035
A20: =Hipótesis!$B$22+(0-3)*$B$4 -> 0.0747 | B20: =((SUMPRODUCT(DCF!$D$21:$M$21,(1+$A20)^(-DCF!$D$22:$M$22))+DCF!$M$17*(1+B$19)/($A20-B$19)*(1+$A20)^(-DCF!$M$22)+Hipótesis!$B$29+Hipótesis!$B$30-Hipótesis!$B$31)/Hipótesis!$B$10*(1+$A20)^(Hipótesis!$B$12/365))/Hipótesis!$B$9-1 -> -0.10317055 | C20: =((SUMPRODUCT(DCF!$D$21:$M$21,(1+$A20)^(-DCF!$D$22:$M$22))+DCF!$M$17*(1+C$19)/($A20-C$19)*(1+$A20)^(-DCF!$M$22)+Hipótesis!$B$29+Hipótesis!$B$30-Hipótesis!$B$31)/Hipótesis!$B$10*(1+$A20)^(Hipótesis!$B$12/365))/Hipótesis!$B$9-1 -> -0.053730204 | D20: =((SUMPRODUCT(DCF!$D$21:$M$21,(1+$A20)^(-DCF!$D$22:$M$22))+DCF!$M$17*(1+D$19)/($A20-D$19)*(1+$A20)^(-DCF!$M$22)+Hipótesis!$B$29+Hipótesis!$B$30-Hipótesis!$B$31)/Hipótesis!$B$10*(1+$A20)^(Hipótesis!$B$12/365))/Hipótesis!$B$9-1 -> 0.0056579017 | E20: =((SUMPRODUCT(DCF!$D$21:$M$21,(1+$A20)^(-DCF!$D$22:$M$22))+DCF!$M$17*(1+E$19)/($A20-E$19)*(1+$A20)^(-DCF!$M$22)+Hipótesis!$B$29+Hipótesis!$B$30-Hipótesis!$B$31)/Hipótesis!$B$10*(1+$A20)^(Hipótesis!$B$12/365))/Hipótesis!$B$9-1 -> 0.078331937 | F20: =((SUMPRODUCT(DCF!$D$21:$M$21,(1+$A20)^(-DCF!$D$22:$M$22))+DCF!$M$17*(1+F$19)/($A20-F$19)*(1+$A20)^(-DCF!$M$22)+Hipótesis!$B$29+Hipótesis!$B$30-Hipótesis!$B$31)/Hipótesis!$B$10*(1+$A20)^(Hipótesis!$B$12/365))/Hipótesis!$B$9-1 -> 0.16931177
A21: =Hipótesis!$B$22+(1-3)*$B$4 -> 0.0797 | B21: =((SUMPRODUCT(DCF!$D$21:$M$21,(1+$A21)^(-DCF!$D$22:$M$22))+DCF!$M$17*(1+B$19)/($A21-B$19)*(1+$A21)^(-DCF!$M$22)+Hipótesis!$B$29+Hipótesis!$B$30-Hipótesis!$B$31)/Hipótesis!$B$10*(1+$A21)^(Hipótesis!$B$12/365))/Hipótesis!$B$9-1 -> -0.1680503 | C21: =((SUMPRODUCT(DCF!$D$21:$M$21,(1+$A21)^(-DCF!$D$22:$M$22))+DCF!$M$17*(1+C$19)/($A21-C$19)*(1+$A21)^(-DCF!$M$22)+Hipótesis!$B$29+Hipótesis!$B$30-Hipótesis!$B$31)/Hipótesis!$B$10*(1+$A21)^(Hipótesis!$B$12/365))/Hipótesis!$B$9-1 -> -0.12774025 | D21: =((SUMPRODUCT(DCF!$D$21:$M$21,(1+$A21)^(-DCF!$D$22:$M$22))+DCF!$M$17*(1+D$19)/($A21-D$19)*(1+$A21)^(-DCF!$M$22)+Hipótesis!$B$29+Hipótesis!$B$30-Hipótesis!$B$31)/Hipótesis!$B$10*(1+$A21)^(Hipótesis!$B$12/365))/Hipótesis!$B$9-1 -> -0.08006091 | E21: =((SUMPRODUCT(DCF!$D$21:$M$21,(1+$A21)^(-DCF!$D$22:$M$22))+DCF!$M$17*(1+E$19)/($A21-E$19)*(1+$A21)^(-DCF!$M$22)+Hipótesis!$B$29+Hipótesis!$B$30-Hipótesis!$B$31)/Hipótesis!$B$10*(1+$A21)^(Hipótesis!$B$12/365))/Hipótesis!$B$9-1 -> -0.022788137 | F21: =((SUMPRODUCT(DCF!$D$21:$M$21,(1+$A21)^(-DCF!$D$22:$M$22))+DCF!$M$17*(1+F$19)/($A21-F$19)*(1+$A21)^(-DCF!$M$22)+Hipótesis!$B$29+Hipótesis!$B$30-Hipótesis!$B$31)/Hipótesis!$B$10*(1+$A21)^(Hipótesis!$B$12/365))/Hipótesis!$B$9-1 -> 0.047297336
A22: =Hipótesis!$B$22+(2-3)*$B$4 -> 0.0847 | B22: =((SUMPRODUCT(DCF!$D$21:$M$21,(1+$A22)^(-DCF!$D$22:$M$22))+DCF!$M$17*(1+B$19)/($A22-B$19)*(1+$A22)^(-DCF!$M$22)+Hipótesis!$B$29+Hipótesis!$B$30-Hipótesis!$B$31)/Hipótesis!$B$10*(1+$A22)^(Hipótesis!$B$12/365))/Hipótesis!$B$9-1 -> -0.22356612 | C22: =((SUMPRODUCT(DCF!$D$21:$M$21,(1+$A22)^(-DCF!$D$22:$M$22))+DCF!$M$17*(1+C$19)/($A22-C$19)*(1+$A22)^(-DCF!$M$22)+Hipótesis!$B$29+Hipótesis!$B$30-Hipótesis!$B$31)/Hipótesis!$B$10*(1+$A22)^(Hipótesis!$B$12/365))/Hipótesis!$B$9-1 -> -0.19026365 | D22: =((SUMPRODUCT(DCF!$D$21:$M$21,(1+$A22)^(-DCF!$D$22:$M$22))+DCF!$M$17*(1+D$19)/($A22-D$19)*(1+$A22)^(-DCF!$M$22)+Hipótesis!$B$29+Hipótesis!$B$30-Hipótesis!$B$31)/Hipótesis!$B$10*(1+$A22)^(Hipótesis!$B$12/365))/Hipótesis!$B$9-1 -> -0.15138289 | E22: =((SUMPRODUCT(DCF!$D$21:$M$21,(1+$A22)^(-DCF!$D$22:$M$22))+DCF!$M$17*(1+E$19)/($A22-E$19)*(1+$A22)^(-DCF!$M$22)+Hipótesis!$B$29+Hipótesis!$B$30-Hipótesis!$B$31)/Hipótesis!$B$10*(1+$A22)^(Hipótesis!$B$12/365))/Hipótesis!$B$9-1 -> -0.10539412 | F22: =((SUMPRODUCT(DCF!$D$21:$M$21,(1+$A22)^(-DCF!$D$22:$M$22))+DCF!$M$17*(1+F$19)/($A22-F$19)*(1+$A22)^(-DCF!$M$22)+Hipótesis!$B$29+Hipótesis!$B$30-Hipótesis!$B$31)/Hipótesis!$B$10*(1+$A22)^(Hipótesis!$B$12/365))/Hipótesis!$B$9-1 -> -0.050152076
A23: =Hipótesis!$B$22+(3-3)*$B$4 -> 0.0897 | B23: =((SUMPRODUCT(DCF!$D$21:$M$21,(1+$A23)^(-DCF!$D$22:$M$22))+DCF!$M$17*(1+B$19)/($A23-B$19)*(1+$A23)^(-DCF!$M$22)+Hipótesis!$B$29+Hipótesis!$B$30-Hipótesis!$B$31)/Hipótesis!$B$10*(1+$A23)^(Hipótesis!$B$12/365))/Hipótesis!$B$9-1 -> -0.27159986 | C23: =((SUMPRODUCT(DCF!$D$21:$M$21,(1+$A23)^(-DCF!$D$22:$M$22))+DCF!$M$17*(1+C$19)/($A23-C$19)*(1+$A23)^(-DCF!$M$22)+Hipótesis!$B$29+Hipótesis!$B$30-Hipótesis!$B$31)/Hipótesis!$B$10*(1+$A23)^(Hipótesis!$B$12/365))/Hipótesis!$B$9-1 -> -0.24377368 | D23: =((SUMPRODUCT(DCF!$D$21:$M$21,(1+$A23)^(-DCF!$D$22:$M$22))+DCF!$M$17*(1+D$19)/($A23-D$19)*(1+$A23)^(-DCF!$M$22)+Hipótesis!$B$29+Hipótesis!$B$30-Hipótesis!$B$31)/Hipótesis!$B$10*(1+$A23)^(Hipótesis!$B$12/365))/Hipótesis!$B$9-1 -> -0.21164669 | E23: =((SUMPRODUCT(DCF!$D$21:$M$21,(1+$A23)^(-DCF!$D$22:$M$22))+DCF!$M$17*(1+E$19)/($A23-E$19)*(1+$A23)^(-DCF!$M$22)+Hipótesis!$B$29+Hipótesis!$B$30-Hipótesis!$B$31)/Hipótesis!$B$10*(1+$A23)^(Hipótesis!$B$12/365))/Hipótesis!$B$9-1 -> -0.1741383 | F23: =((SUMPRODUCT(DCF!$D$21:$M$21,(1+$A23)^(-DCF!$D$22:$M$22))+DCF!$M$17*(1+F$19)/($A23-F$19)*(1+$A23)^(-DCF!$M$22)+Hipótesis!$B$29+Hipótesis!$B$30-Hipótesis!$B$31)/Hipótesis!$B$10*(1+$A23)^(Hipótesis!$B$12/365))/Hipótesis!$B$9-1 -> -0.1297728
A24: =Hipótesis!$B$22+(4-3)*$B$4 -> 0.0947 | B24: =((SUMPRODUCT(DCF!$D$21:$M$21,(1+$A24)^(-DCF!$D$22:$M$22))+DCF!$M$17*(1+B$19)/($A24-B$19)*(1+$A24)^(-DCF!$M$22)+Hipótesis!$B$29+Hipótesis!$B$30-Hipótesis!$B$31)/Hipótesis!$B$10*(1+$A24)^(Hipótesis!$B$12/365))/Hipótesis!$B$9-1 -> -0.3135611 | C24: =((SUMPRODUCT(DCF!$D$21:$M$21,(1+$A24)^(-DCF!$D$22:$M$22))+DCF!$M$17*(1+C$19)/($A24-C$19)*(1+$A24)^(-DCF!$M$22)+Hipótesis!$B$29+Hipótesis!$B$30-Hipótesis!$B$31)/Hipótesis!$B$10*(1+$A24)^(Hipótesis!$B$12/365))/Hipótesis!$B$9-1 -> -0.29008137 | D24: =((SUMPRODUCT(DCF!$D$21:$M$21,(1+$A24)^(-DCF!$D$22:$M$22))+DCF!$M$17*(1+D$19)/($A24-D$19)*(1+$A24)^(-DCF!$M$22)+Hipótesis!$B$29+Hipótesis!$B$30-Hipótesis!$B$31)/Hipótesis!$B$10*(1+$A24)^(Hipótesis!$B$12/365))/Hipótesis!$B$9-1 -> -0.26323295 | E24: =((SUMPRODUCT(DCF!$D$21:$M$21,(1+$A24)^(-DCF!$D$22:$M$22))+DCF!$M$17*(1+E$19)/($A24-E$19)*(1+$A24)^(-DCF!$M$22)+Hipótesis!$B$29+Hipótesis!$B$30-Hipótesis!$B$31)/Hipótesis!$B$10*(1+$A24)^(Hipótesis!$B$12/365))/Hipótesis!$B$9-1 -> -0.23223485 | F24: =((SUMPRODUCT(DCF!$D$21:$M$21,(1+$A24)^(-DCF!$D$22:$M$22))+DCF!$M$17*(1+F$19)/($A24-F$19)*(1+$A24)^(-DCF!$M$22)+Hipótesis!$B$29+Hipótesis!$B$30-Hipótesis!$B$31)/Hipótesis!$B$10*(1+$A24)^(Hipótesis!$B$12/365))/Hipótesis!$B$9-1 -> -0.19604444
A25: =Hipótesis!$B$22+(5-3)*$B$4 -> 0.0997 | B25: =((SUMPRODUCT(DCF!$D$21:$M$21,(1+$A25)^(-DCF!$D$22:$M$22))+DCF!$M$17*(1+B$19)/($A25-B$19)*(1+$A25)^(-DCF!$M$22)+Hipótesis!$B$29+Hipótesis!$B$30-Hipótesis!$B$31)/Hipótesis!$B$10*(1+$A25)^(Hipótesis!$B$12/365))/Hipótesis!$B$9-1 -> -0.35052652 | C25: =((SUMPRODUCT(DCF!$D$21:$M$21,(1+$A25)^(-DCF!$D$22:$M$22))+DCF!$M$17*(1+C$19)/($A25-C$19)*(1+$A25)^(-DCF!$M$22)+Hipótesis!$B$29+Hipótesis!$B$30-Hipótesis!$B$31)/Hipótesis!$B$10*(1+$A25)^(Hipótesis!$B$12/365))/Hipótesis!$B$9-1 -> -0.33054326 | D25: =((SUMPRODUCT(DCF!$D$21:$M$21,(1+$A25)^(-DCF!$D$22:$M$22))+DCF!$M$17*(1+D$19)/($A25-D$19)*(1+$A25)^(-DCF!$M$22)+Hipótesis!$B$29+Hipótesis!$B$30-Hipótesis!$B$31)/Hipótesis!$B$10*(1+$A25)^(Hipótesis!$B$12/365))/Hipótesis!$B$9-1 -> -0.30788487 | E25: =((SUMPRODUCT(DCF!$D$21:$M$21,(1+$A25)^(-DCF!$D$22:$M$22))+DCF!$M$17*(1+E$19)/($A25-E$19)*(1+$A25)^(-DCF!$M$22)+Hipótesis!$B$29+Hipótesis!$B$30-Hipótesis!$B$31)/Hipótesis!$B$10*(1+$A25)^(Hipótesis!$B$12/365))/Hipótesis!$B$9-1 -> -0.28197564 | F25: =((SUMPRODUCT(DCF!$D$21:$M$21,(1+$A25)^(-DCF!$D$22:$M$22))+DCF!$M$17*(1+F$19)/($A25-F$19)*(1+$A25)^(-DCF!$M$22)+Hipótesis!$B$29+Hipótesis!$B$30-Hipótesis!$B$31)/Hipótesis!$B$10*(1+$A25)^(Hipótesis!$B$12/365))/Hipótesis!$B$9-1 -> -0.25206189
A26: =Hipótesis!$B$22+(6-3)*$B$4 -> 0.1047 | B26: =((SUMPRODUCT(DCF!$D$21:$M$21,(1+$A26)^(-DCF!$D$22:$M$22))+DCF!$M$17*(1+B$19)/($A26-B$19)*(1+$A26)^(-DCF!$M$22)+Hipótesis!$B$29+Hipótesis!$B$30-Hipótesis!$B$31)/Hipótesis!$B$10*(1+$A26)^(Hipótesis!$B$12/365))/Hipótesis!$B$9-1 -> -0.38333268 | C26: =((SUMPRODUCT(DCF!$D$21:$M$21,(1+$A26)^(-DCF!$D$22:$M$22))+DCF!$M$17*(1+C$19)/($A26-C$19)*(1+$A26)^(-DCF!$M$22)+Hipótesis!$B$29+Hipótesis!$B$30-Hipótesis!$B$31)/Hipótesis!$B$10*(1+$A26)^(Hipótesis!$B$12/365))/Hipótesis!$B$9-1 -> -0.36619555 | D26: =((SUMPRODUCT(DCF!$D$21:$M$21,(1+$A26)^(-DCF!$D$22:$M$22))+DCF!$M$17*(1+D$19)/($A26-D$19)*(1+$A26)^(-DCF!$M$22)+Hipótesis!$B$29+Hipótesis!$B$30-Hipótesis!$B$31)/Hipótesis!$B$10*(1+$A26)^(Hipótesis!$B$12/365))/Hipótesis!$B$9-1 -> -0.34690821 | E26: =((SUMPRODUCT(DCF!$D$21:$M$21,(1+$A26)^(-DCF!$D$22:$M$22))+DCF!$M$17*(1+E$19)/($A26-E$19)*(1+$A26)^(-DCF!$M$22)+Hipótesis!$B$29+Hipótesis!$B$30-Hipótesis!$B$31)/Hipótesis!$B$10*(1+$A26)^(Hipótesis!$B$12/365))/Hipótesis!$B$9-1 -> -0.32503891 | F26: =((SUMPRODUCT(DCF!$D$21:$M$21,(1+$A26)^(-DCF!$D$22:$M$22))+DCF!$M$17*(1+F$19)/($A26-F$19)*(1+$A26)^(-DCF!$M$22)+Hipótesis!$B$29+Hipótesis!$B$30-Hipótesis!$B$31)/Hipótesis!$B$10*(1+$A26)^(Hipótesis!$B$12/365))/Hipótesis!$B$9-1 -> -0.30003196
A29: Control: la celda central de la primera tabla debe coincidir con el valor del DCF
A30: Diferencia (debe ser 0) | B30: =ROUND(D12-DCF!C40,6) -> 0

Sheet Comparables
A1: Valoración por comparables
A2: ¿Qué valdría Inditex si el mercado la valorase como a H&M, Fast Retailing o Next? Datos de una sola fuente (Yahoo Finance) y la misma fecha.
A4: 1. Múltiplos de mercado (Yahoo Finance, 07/10/2026)
A5: Empresa | B5: P/E trailing | C5: P/E forward | D5: EV/EBITDA | E5: Margen operativo (%) | F5: ROE (%) | G5: Crec. ventas trim. (%) | H5: Beta Yahoo 5a
A6: Inditex | B6: 25.8 | C6: 24.63 | D6: 13.51 | E6: 18.92 | F6: 36.82 | G6: 9.1 | H6: 0.96
A7: H&M | B7: 21.64 | C7: 20.33 | D7: 7.72 | E7: 10.74 | F7: 33.25 | G7: 0.3 | H7: 1.05
A8: Fast Retailing | B8: 43.44 | C8: 35.97 | D8: 20.18 | E8: 21 | F8: 22.48 | G8: 22.2 | H8: 0.5
A9: Next | B9: 18.35 | C9: 16.61 | D9: 10.91 | E9: 17.7 | F9: 54.54 | G9: 9.6 | H9: 1.07
A10: Mediana de los comparables | B10: =MEDIAN(B7:B9) -> 21.64 | C10: =MEDIAN(C7:C9) -> 20.33 | D10: =MEDIAN(D7:D9) -> 10.91 | E10: =MEDIAN(E7:E9) -> 17.7 | F10: =MEDIAN(F7:F9) -> 33.25 | G10: =MEDIAN(G7:G9) -> 9.6 | H10: =MEDIAN(H7:H9) -> 1.05
A11: Media de los comparables | B11: =AVERAGE(B7:B9) -> 27.81 | C11: =AVERAGE(C7:C9) -> 24.303333 | D11: =AVERAGE(D7:D9) -> 12.936667 | E11: =AVERAGE(E7:E9) -> 16.48 | F11: =AVERAGE(F7:F9) -> 36.756667 | G11: =AVERAGE(G7:G9) -> 10.7 | H11: =AVERAGE(H7:H9) -> 0.87333333
A12: Inditex frente a la mediana (prima + / descuento −) | B12: =B6/B10-1 -> 0.1922366 | C12: =C6/C10-1 -> 0.21151008 | D12: =D6/D10-1 -> 0.23831347
A14: 2. Datos de Inditex para aplicar los múltiplos
A15: EBITDA de los últimos 12 meses (M€) | B15: 11666 | D15: Ejercicio 2025 (11.267) − 1S2025 (5.114) + 1S2026 (5.513). Resultados oficiales de Inditex
A16: BPA forward de Inditex (€) | B16: =B20/C6 -> 2.2078766 | D16: Precio ÷ P/E forward de Yahoo: el beneficio por acción que está implícito en ese múltiplo
A17: Pasivos por arrendamiento (M€) | B17: =Hipótesis!B32 -> 6197 | D17: Se restan porque el EV de Yahoo incluye los alquileres como deuda
A18: Posición financiera neta (M€) | B18: =Hipótesis!B29 -> 10398 | D18: Caja + inversiones temporales − deuda financiera (31/07/2026)
A19: Acciones (millones) | B19: =Hipótesis!B10 -> 3115.9215
A20: Precio de mercado (€) | B20: =Hipótesis!B9 -> 54.38
A22: 3. Valor por acción de Inditex si se valorase como cada comparable (€)
B23: Por P/E forward | C23: Por EV/EBITDA
A24: =A7 -> H&M | B24: =C7*$B$16 -> 44.886131 | C24: =(D7*$B$15-$B$17+$B$18)/$B$19 -> 30.251891
A25: =A8 -> Fast Retailing | B25: =C8*$B$16 -> 79.41732 | C25: =(D8*$B$15-$B$17+$B$18)/$B$19 -> 76.90209
A26: =A9 -> Next | B26: =C9*$B$16 -> 36.67283 | C26: =(D9*$B$15-$B$17+$B$18)/$B$19 -> 42.195241
A27: Mínimo | B27: =MIN(B24:B26) -> 36.67283 | C27: =MIN(C24:C26) -> 30.251891
A28: Mediana | B28: =MEDIAN(B24:B26) -> 44.886131 | C28: =MEDIAN(C24:C26) -> 42.195241
A29: Media | B29: =AVERAGE(B24:B26) -> 53.65876 | C29: =AVERAGE(C24:C26) -> 49.783074
A30: Máximo | B30: =MAX(B24:B26) -> 79.41732 | C30: =MAX(C24:C26) -> 76.90209
A31: Media sin Fast Retailing (crecimiento ≈22 %) | B31: =AVERAGE(B24,B26) -> 40.77948 | C31: =AVERAGE(C24,C26) -> 36.223566
A32: Control: el múltiplo propio de Inditex aplicado a Inditex | B32: =C6*$B$16 -> 54.38 | C32: =(D6*$B$15-$B$17+$B$18)/$B$19 -> 51.929632
A33: Diferencia frente al precio de mercado | B33: =B32/$B$20-1 -> 0 | C33: =C32/$B$20-1 -> -0.045060089 | D33: La diferencia en EV/EBITDA viene de cómo Yahoo define el EBITDA de Inditex (≈11.900 M€ frente a los 11.666 M€ de aquí)
A35: 4. Campo de fútbol: rangos de valor por acción (€)
A36: Método | B36: Mínimo | C36: Máximo | D36: Amplitud | E36: Valor central
A37: DCF (escenarios Bajo - Alto) | B37: =Resumen!C17 -> 32.726328 | C37: =Resumen!C19 -> 51.747125 | D37: =C37-B37 -> 19.020797 | E37: =Resumen!C18 -> 42.870653
A38: Comparables: P/E forward | B38: =B27 -> 36.67283 | C38: =B30 -> 79.41732 | D38: =C38-B38 -> 42.74449 | E38: =B28 -> 44.886131
A39: Comparables: EV/EBITDA | B39: =C27 -> 30.251891 | C39: =C30 -> 76.90209 | D39: =C39-B39 -> 46.650199 | E39: =C28 -> 42.195241
A40: Precio objetivo de analistas | B40: 41.5 | C40: 65 | D40: =C40-B40 -> 23.5 | E40: 59.54
A41: Rango de cotización 52 semanas | B41: 46.07 | C41: 59.42 | D41: =C41-B41 -> 13.35
A42: Precio de mercado | B42: =B20 -> 54.38 | D42: Analistas: 24 analistas, Bolsamanía 31/08/2026. 52 semanas: Yahoo Finance 07/10/2026. DCF: foto estática de la hoja Resumen.
